Thu Jul 4 18:31:03 EDT 2024: Job 12851319 is allocated resources.
Inside slurm_launcher.slrm (/var/spool/slurmd/job12851319/slurm_script). received arguments: main.py --output-dir results/models/laplace --model-name equiformer_v2 --data-path datasets/qm9 --model-type Laplace --epochs 200 --iterations 30 --seed 0
Namespace(output_dir='results/models/laplace', model_name='equiformer_v2', model_type='Laplace', input_irreps=None, radius=5.0, num_basis=32, output_channels=1, epochs=200, iterations=30, batch_size=64, model_ema=True, model_ema_decay=0.9999, model_ema_force_cpu=False, drop_path_rate=0.1, patience=50, opt='adamw', opt_eps=1e-08, opt_betas=None, clip_grad=None, momentum=0.9, weight_decay=0.01, sched='cosine', lr=0.0005, lr_noise=None, lr_noise_pct=0.67, lr_noise_std=1.0, warmup_lr=1e-06, min_lr=1e-05, decay_epochs=30, warmup_epochs=5, cooldown_epochs=10, patience_epochs=10, decay_rate=0.1, print_freq=100, target=4, data_path='datasets/qm9', feature_type='one_hot', compute_stats=False, standardize=True, loss='l1', seed=0, workers=4, pin_mem=True, amp=False, prototyping=True, noise_sigma=0.02, denoising_coef=0.1, denoising_prob=0.5, corrupt_ratio=0.125)
wandb: Currently logged in as: andresguzco. Use `wandb login --relogin` to force relogin
wandb: - Waiting for wandb.init()...wandb: ERROR Error while calling W&B API: An internal error occurred. Please contact support. (<Response [500]>)
wandb: \ Waiting for wandb.init()...wandb: | Waiting for wandb.init()...wandb: / Waiting for wandb.init()...wandb: - Waiting for wandb.init()...wandb: \ Waiting for wandb.init()...wandb: | Waiting for wandb.init()...wandb: / Waiting for wandb.init()...wandb: - Waiting for wandb.init()...wandb: \ Waiting for wandb.init()...wandb: | Waiting for wandb.init()...wandb: / Waiting for wandb.init()...wandb: - Waiting for wandb.init()...wandb: \ Waiting for wandb.init()...wandb: | Waiting for wandb.init()...wandb: / Waiting for wandb.init()...wandb: - Waiting for wandb.init()...wandb: \ Waiting for wandb.init()...wandb: | Waiting for wandb.init()...wandb: / Waiting for wandb.init()...wandb: - Waiting for wandb.init()...wandb: \ Waiting for wandb.init()...wandb: | Waiting for wandb.init()...wandb: / Waiting for wandb.init()...wandb: - Waiting for wandb.init()...wandb: \ Waiting for wandb.init()...wandb: | Waiting for wandb.init()...wandb: / Waiting for wandb.init()...wandb: - Waiting for wandb.init()...wandb: \ Waiting for wandb.init()...wandb: | Waiting for wandb.init()...wandb: / Waiting for wandb.init()...wandb: - Waiting for wandb.init()...wandb: \ Waiting for wandb.init()...wandb: | Waiting for wandb.init()...wandb: / Waiting for wandb.init()...wandb: - Waiting for wandb.init()...wandb: \ Waiting for wandb.init()...wandb: | Waiting for wandb.init()...wandb: / Waiting for wandb.init()...wandb: - Waiting for wandb.init()...wandb: \ Waiting for wandb.init()...wandb: | Waiting for wandb.init()...wandb: / Waiting for wandb.init()...wandb: - Waiting for wandb.init()...wandb: Network error (ReadTimeout), entering retry loop.
wandb: \ Waiting for wandb.init()...wandb: | Waiting for wandb.init()...wandb: / Waiting for wandb.init()...wandb: - Waiting for wandb.init()...wandb: \ Waiting for wandb.init()...wandb: | Waiting for wandb.init()...wandb: / Waiting for wandb.init()...wandb: - Waiting for wandb.init()...wandb: \ Waiting for wandb.init()...wandb: | Waiting for wandb.init()...wandb: / Waiting for wandb.init()...wandb: - Waiting for wandb.init()...wandb: \ Waiting for wandb.init()...wandb: | Waiting for wandb.init()...wandb: / Waiting for wandb.init()...wandb: - Waiting for wandb.init()...wandb: \ Waiting for wandb.init()...wandb: | Waiting for wandb.init()...wandb: / Waiting for wandb.init()...wandb: - Waiting for wandb.init()...wandb: ERROR Error while calling W&B API: An internal error occurred. Please contact support. (<Response [500]>)
wandb: \ Waiting for wandb.init()...wandb: | Waiting for wandb.init()...wandb: / Waiting for wandb.init()...wandb: - Waiting for wandb.init()...wandb: \ Waiting for wandb.init()...wandb: | Waiting for wandb.init()...wandb: / Waiting for wandb.init()...wandb: - Waiting for wandb.init()...wandb: \ Waiting for wandb.init()...wandb: | Waiting for wandb.init()...wandb: ERROR Error while calling W&B API: An internal error occurred. Please contact support. (<Response [500]>)
wandb: / Waiting for wandb.init()...wandb: - Waiting for wandb.init()...wandb: \ Waiting for wandb.init()...wandb: | Waiting for wandb.init()...wandb: / Waiting for wandb.init()...wandb: - Waiting for wandb.init()...wandb: \ Waiting for wandb.init()...wandb: | Waiting for wandb.init()...wandb: / Waiting for wandb.init()...wandb: - Waiting for wandb.init()...wandb: \ Waiting for wandb.init()...wandb: | Waiting for wandb.init()...wandb: / Waiting for wandb.init()...wandb: - Waiting for wandb.init()...wandb: ERROR Run initialization has timed out after 90.0 sec. 
wandb: ERROR Please refer to the documentation for additional information: https://docs.wandb.ai/guides/track/tracking-faq#initstarterror-error-communicating-with-wandb-process-
Traceback (most recent call last):
  File "/h/aguzmanc/3D_Bayes/main.py", line 230, in <module>
    main(args)
  File "/h/aguzmanc/3D_Bayes/main.py", line 44, in main
    run = wandb.init(
  File "/h/aguzmanc/miniforge3/envs/equibayes/lib/python3.10/site-packages/wandb/sdk/wandb_init.py", line 1178, in init
    wandb._sentry.reraise(e)
  File "/h/aguzmanc/miniforge3/envs/equibayes/lib/python3.10/site-packages/wandb/analytics/sentry.py", line 155, in reraise
    raise exc.with_traceback(sys.exc_info()[2])
  File "/h/aguzmanc/miniforge3/envs/equibayes/lib/python3.10/site-packages/wandb/sdk/wandb_init.py", line 1164, in init
    return wi.init()
  File "/h/aguzmanc/miniforge3/envs/equibayes/lib/python3.10/site-packages/wandb/sdk/wandb_init.py", line 776, in init
    raise error
wandb.errors.CommError: Run initialization has timed out after 90.0 sec. 
Please refer to the documentation for additional information: https://docs.wandb.ai/guides/track/tracking-faq#initstarterror-error-communicating-with-wandb-process-
